<?xml version='1.0'?>
<sdf version='1.3'>
    <model name="Joint planes">
        
    <pose>0 0 0.5 0 0 0</pose>
    
    <link name="link">
        
        <self_collide> true </self_collide>
        
        <collision name="collision">
            
            <geometry>
                <box>
                    <size> 1 1 0.1 </size>
                </box>
            </geometry>
            
        </collision>
        
        <visual name="visual">
            
            <geometry>
                <box>
                    <size> 1 1 0.1 </size>
                </box>
            </geometry>
            
            <material>
                <script>
                    <uri>file://media/materials/scripts/gazebo.material</uri>
                    <name>Gazebo/Red</name>
                </script>
            </material>
        </visual>
        
    </link>
    
    <link name="link2">
        
        <self_collide> true </self_collide>
        
        <pose> 0 0 0.3 0 0 0 </pose>
        
        <collision name="collisionx">
            <geometry>
                <box>
                    <size> 1 1 0.1 </size>
                </box>
            </geometry>
        </collision>
        
        <visual name="visualx">
            <geometry>
                <box>
                    <size> 1 1 0.1 </size>
                </box>
            </geometry>
            <material>
                <script>
                    <uri>file://media/materials/scripts/gazebo.material</uri>
                    <name>Gazebo/Green</name>
                </script>
            </material>
        </visual>
    </link>
    
    <joint type="revolute" name="two_planes">
        <parent> link </parent>
        <child> link2 </child>
        <pose> 0.5 0 0 0 0 0 </pose>
        <axis>
            <xyz> 0 1 0 </xyz>
        </axis>
        
        <physics>
            <ode>
                <limit>
                    <cfm>0.0</cfm>
                    <erp>0.9</erp>
                </limit> 
            </ode>
        </physics>
    </joint>
    
    </model>
</sdf>