<sdf version='1.6'>
  <model name='robotiq-3f-gripper_articulated'>
    <link name='palm'>
      <pose frame=''>0 0 0 0 -0 0</pose>
      <inertial>
        <pose frame=''>0.0455 0.0214 0 0 -0 0</pose>
        <mass>0.05</mass>
        <inertia>
          <ixx>0.000800038</ixx>
          <ixy>2.73262e-05</ixy>
          <ixz>7.96327e-09</ixz>
          <iyy>0.00999996</iyy>
          <iyz>1e-05</iyz>
          <izz>0.001</izz>
        </inertia>
      </inertial>
      <collision name='palm_collision'>
        <pose frame=''>0 0 0 0 -0 0</pose>
        <geometry>
          <mesh>
            <scale>1 1 1</scale>
            <uri>model://robotiq_3f_gripper_visualization/meshes/robotiq-3f-gripper_articulated/collision/palm.STL</uri>
          </mesh>
        </geometry>
      </collision>
      <collision name='palm_fixed_joint_lump__finger_middle_link_0_collision_1'>
        <pose frame=''>0.045516 0.0414 0 0 -0 1.57</pose>
        <geometry>
          <mesh>
            <scale>1 1 1</scale>
            <uri>model://robotiq_3f_gripper_visualization/meshes/robotiq-3f-gripper_articulated/collision/link_0.STL</uri>
          </mesh>
        </geometry>
      </collision>
      <visual name='palm_visual'>
        <pose frame=''>0 0 0 0 -0 0</pose>
        <geometry>
          <mesh>
            <scale>1 1 1</scale>
            <uri>model://robotiq_3f_gripper_visualization/meshes/robotiq-3f-gripper_articulated/visual/palm.STL</uri>
          </mesh>
        </geometry>
      </visual>
      <visual name='palm_fixed_joint_lump__finger_middle_link_0_visual_1'>
        <pose frame=''>0.045516 0.0414 0 0 -0 1.57</pose>
        <geometry>
          <mesh>
            <scale>1 1 1</scale>
            <uri>model://robotiq_3f_gripper_visualization/meshes/robotiq-3f-gripper_articulated/visual/link_0.STL</uri>
          </mesh>
        </geometry>
      </visual>
    </link>
    <link name='finger_1_link_0'>
      <pose frame=''>-0.0455 0.0214 0.036 3.14159 -7e-06 1.57159</pose>
      <inertial>
        <pose frame=''>0 0 0 0 -0 0</pose>
        <mass>0.05</mass>
        <inertia>
          <ixx>0.01</ixx>
          <ixy>-2e-05</ixy>
          <ixz>1e-05</ixz>
          <iyy>0.0008</iyy>
          <iyz>0</iyz>
          <izz>0.001</izz>
        </inertia>
      </inertial>
      <collision name='finger_1_link_0_collision'>
        <pose frame=''>0.02 0 0 0 -0 0</pose>
        <geometry>
          <mesh>
            <scale>1 1 1</scale>
            <uri>model://robotiq_3f_gripper_visualization/meshes/robotiq-3f-gripper_articulated/collision/link_0.STL</uri>
          </mesh>
        </geometry>
      </collision>
      <visual name='finger_1_link_0_visual'>
        <pose frame=''>0.02 0 0 0 -0 0</pose>
        <geometry>
          <mesh>
            <scale>1 1 1</scale>
            <uri>model://robotiq_3f_gripper_visualization/meshes/robotiq-3f-gripper_articulated/visual/link_0.STL</uri>
          </mesh>
        </geometry>
      </visual>
    </link>
    <joint name='palm_finger_1_joint' type='revolute'>
      <child>finger_1_link_0</child>
      <parent>palm</parent>
      <axis>
        <xyz>1 0.000796 0</xyz>
        <limit>
          <lower>-0.1784</lower>
          <upper>0.192</upper>
          <effort>100</effort>
          <velocity>100</velocity>
        </limit>
        <dynamics>
          <spring_reference>0</spring_reference>
          <spring_stiffness>0</spring_stiffness>
        </dynamics>
        <use_parent_model_frame>1</use_parent_model_frame>
      </axis>
    </joint>
    <link name='finger_1_link_1'>
      <pose frame=''>-0.045516 0.0414 0.036 3.14159 -7e-06 1.57159</pose>
      <inertial>
        <pose frame=''>0 0 0 0 -0 0</pose>
        <mass>0.15</mass>
        <inertia>
          <ixx>0.001859</ixx>
          <ixy>-0.000376</ixy>
          <ixz>2.8e-05</ixz>
          <iyy>0.012756</iyy>
          <iyz>0</iyz>
          <izz>0.0024</izz>
        </inertia>
      </inertial>
      <collision name='finger_1_link_1_collision'>
        <pose frame=''>0.05 -0.028 0 0 0 -0.52</pose>
        <geometry>
          <mesh>
            <scale>1 1 1</scale>
            <uri>model://robotiq_3f_gripper_visualization/meshes/robotiq-3f-gripper_articulated/collision/link_1.STL</uri>
          </mesh>
        </geometry>
      </collision>
      <visual name='finger_1_link_1_visual'>
        <pose frame=''>0.05 -0.028 0 0 0 -0.52</pose>
        <geometry>
          <mesh>
            <scale>1 1 1</scale>
            <uri>model://robotiq_3f_gripper_visualization/meshes/robotiq-3f-gripper_articulated/visual/link_1.STL</uri>
          </mesh>
        </geometry>
      </visual>
    </link>
    <joint name='finger_1_joint_1' type='revolute'>
      <child>finger_1_link_1</child>
      <parent>finger_1_link_0</parent>
      <axis>
        <xyz>-0 7e-06 -1</xyz>
        <limit>
          <lower>0.0495</lower>
          <upper>1.2218</upper>
          <effort>100</effort>
          <velocity>100</velocity>
        </limit>
        <dynamics>
          <spring_reference>0</spring_reference>
          <spring_stiffness>0</spring_stiffness>
        </dynamics>
        <use_parent_model_frame>1</use_parent_model_frame>
      </axis>
    </joint>
    <link name='finger_1_link_2'>
      <pose frame=''>-0.073556 0.091378 0.036001 3.14159 -6e-06 2.09159</pose>
      <inertial>
        <pose frame=''>0 0 0 0 -0 0</pose>
        <mass>0.15</mass>
        <inertia>
          <ixx>0.001859</ixx>
          <ixy>-0.000376</ixy>
          <ixz>2.8e-05</ixz>
          <iyy>0.012756</iyy>
          <iyz>0</iyz>
          <izz>0.0024</izz>
        </inertia>
      </inertial>
      <collision name='finger_1_link_2_collision'>
        <pose frame=''>0.039 0 0.0075 0 -0 0</pose>
        <geometry>
          <mesh>
            <scale>1 1 1</scale>
            <uri>model://robotiq_3f_gripper_visualization/meshes/robotiq-3f-gripper_articulated/collision/link_2.STL</uri>
          </mesh>
        </geometry>
      </collision>
      <visual name='finger_1_link_2_visual'>
        <pose frame=''>0.039 0 0.0075 0 -0 0</pose>
        <geometry>
          <mesh>
            <scale>1 1 1</scale>
            <uri>model://robotiq_3f_gripper_visualization/meshes/robotiq-3f-gripper_articulated/visual/link_2.STL</uri>
          </mesh>
        </geometry>
      </visual>
    </link>
    <joint name='finger_1_joint_2' type='revolute'>
      <child>finger_1_link_2</child>
      <parent>finger_1_link_1</parent>
      <axis>
        <xyz>-0 7e-06 -1</xyz>
        <limit>
          <lower>0</lower>
          <upper>1.5708</upper>
          <effort>100</effort>
          <velocity>100</velocity>
        </limit>
        <dynamics>
          <spring_reference>0</spring_reference>
          <spring_stiffness>0</spring_stiffness>
        </dynamics>
        <use_parent_model_frame>1</use_parent_model_frame>
      </axis>
    </joint>
    <link name='finger_1_link_3'>
      <pose frame=''>-0.092961 0.125207 0.036001 3.14159 -6e-06 2.09159</pose>
      <inertial>
        <pose frame=''>0 0 0 0 -0 0</pose>
        <mass>0.05</mass>
        <inertia>
          <ixx>0.001239</ixx>
          <ixy>-0.000251</ixy>
          <ixz>1.9e-05</ixz>
          <iyy>0.00085</iyy>
          <iyz>0</iyz>
          <izz>0.001632</izz>
        </inertia>
      </inertial>
      <collision name='finger_1_link_3_collision'>
        <pose frame=''>0 0 0 0 -0 0.52</pose>
        <geometry>
          <mesh>
            <scale>1 1 1</scale>
            <uri>model://robotiq_3f_gripper_visualization/meshes/robotiq-3f-gripper_articulated/collision/link_3.STL</uri>
          </mesh>
        </geometry>
      </collision>
      <visual name='finger_1_link_3_visual'>
        <pose frame=''>0 0 0 0 -0 0.52</pose>
        <geometry>
          <mesh>
            <scale>1 1 1</scale>
            <uri>model://robotiq_3f_gripper_visualization/meshes/robotiq-3f-gripper_articulated/visual/link_3.STL</uri>
          </mesh>
        </geometry>
      </visual>
    </link>
    <joint name='finger_1_joint_3' type='revolute'>
      <child>finger_1_link_3</child>
      <parent>finger_1_link_2</parent>
      <axis>
        <xyz>-0 7e-06 -1</xyz>
        <limit>
          <lower>-1.2217</lower>
          <upper>-0.0523</upper>
          <effort>100</effort>
          <velocity>100</velocity>
        </limit>
        <dynamics>
          <spring_reference>0</spring_reference>
          <spring_stiffness>0</spring_stiffness>
        </dynamics>
        <use_parent_model_frame>1</use_parent_model_frame>
      </axis>
    </joint>
    <link name='finger_2_link_0'>
      <pose frame=''>-0.0455 0.0214 -0.036 3.14159 -7e-06 1.57159</pose>
      <inertial>
        <pose frame=''>0 0 0 0 -0 0</pose>
        <mass>0.05</mass>
        <inertia>
          <ixx>0.01</ixx>
          <ixy>-2e-05</ixy>
          <ixz>1e-05</ixz>
          <iyy>0.0008</iyy>
          <iyz>0</iyz>
          <izz>0.001</izz>
        </inertia>
      </inertial>
      <collision name='finger_2_link_0_collision'>
        <pose frame=''>0.02 0 0 0 -0 0</pose>
        <geometry>
          <mesh>
            <scale>1 1 1</scale>
            <uri>model://robotiq_3f_gripper_visualization/meshes/robotiq-3f-gripper_articulated/collision/link_0.STL</uri>
          </mesh>
        </geometry>
      </collision>
      <visual name='finger_2_link_0_visual'>
        <pose frame=''>0.02 0 0 0 -0 0</pose>
        <geometry>
          <mesh>
            <scale>1 1 1</scale>
            <uri>model://robotiq_3f_gripper_visualization/meshes/robotiq-3f-gripper_articulated/visual/link_0.STL</uri>
          </mesh>
        </geometry>
      </visual>
    </link>
    <joint name='palm_finger_2_joint' type='revolute'>
      <child>finger_2_link_0</child>
      <parent>palm</parent>
      <axis>
        <xyz>1 0.000796 0</xyz>
        <limit>
          <lower>-0.192</lower>
          <upper>0.1784</upper>
          <effort>100</effort>
          <velocity>100</velocity>
        </limit>
        <dynamics>
          <spring_reference>0</spring_reference>
          <spring_stiffness>0</spring_stiffness>
        </dynamics>
        <use_parent_model_frame>1</use_parent_model_frame>
      </axis>
    </joint>
    <link name='finger_2_link_1'>
      <pose frame=''>-0.045516 0.0414 -0.036 3.14159 -7e-06 1.57159</pose>
      <inertial>
        <pose frame=''>0 0 0 0 -0 0</pose>
        <mass>0.15</mass>
        <inertia>
          <ixx>0.001859</ixx>
          <ixy>-0.000376</ixy>
          <ixz>2.8e-05</ixz>
          <iyy>0.012756</iyy>
          <iyz>0</iyz>
          <izz>0.0024</izz>
        </inertia>
      </inertial>
      <collision name='finger_2_link_1_collision'>
        <pose frame=''>0.05 -0.028 0 0 0 -0.52</pose>
        <geometry>
          <mesh>
            <scale>1 1 1</scale>
            <uri>model://robotiq_3f_gripper_visualization/meshes/robotiq-3f-gripper_articulated/collision/link_1.STL</uri>
          </mesh>
        </geometry>
      </collision>
      <visual name='finger_2_link_1_visual'>
        <pose frame=''>0.05 -0.028 0 0 0 -0.52</pose>
        <geometry>
          <mesh>
            <scale>1 1 1</scale>
            <uri>model://robotiq_3f_gripper_visualization/meshes/robotiq-3f-gripper_articulated/visual/link_1.STL</uri>
          </mesh>
        </geometry>
      </visual>
    </link>
    <joint name='finger_2_joint_1' type='revolute'>
      <child>finger_2_link_1</child>
      <parent>finger_2_link_0</parent>
      <axis>
        <xyz>-0 7e-06 -1</xyz>
        <limit>
          <lower>0.0495</lower>
          <upper>1.2218</upper>
          <effort>100</effort>
          <velocity>100</velocity>
        </limit>
        <dynamics>
          <spring_reference>0</spring_reference>
          <spring_stiffness>0</spring_stiffness>
        </dynamics>
        <use_parent_model_frame>1</use_parent_model_frame>
      </axis>
    </joint>
    <link name='finger_2_link_2'>
      <pose frame=''>-0.073556 0.091378 -0.036 3.14159 -6e-06 2.09159</pose>
      <inertial>
        <pose frame=''>0 0 0 0 -0 0</pose>
        <mass>0.15</mass>
        <inertia>
          <ixx>0.001859</ixx>
          <ixy>-0.000376</ixy>
          <ixz>2.8e-05</ixz>
          <iyy>0.012756</iyy>
          <iyz>0</iyz>
          <izz>0.0024</izz>
        </inertia>
      </inertial>
      <collision name='finger_2_link_2_collision'>
        <pose frame=''>0.039 0 0.0075 0 -0 0</pose>
        <geometry>
          <mesh>
            <scale>1 1 1</scale>
            <uri>model://robotiq_3f_gripper_visualization/meshes/robotiq-3f-gripper_articulated/collision/link_2.STL</uri>
          </mesh>
        </geometry>
      </collision>
      <visual name='finger_2_link_2_visual'>
        <pose frame=''>0.039 0 0.0075 0 -0 0</pose>
        <geometry>
          <mesh>
            <scale>1 1 1</scale>
            <uri>model://robotiq_3f_gripper_visualization/meshes/robotiq-3f-gripper_articulated/visual/link_2.STL</uri>
          </mesh>
        </geometry>
      </visual>
    </link>
    <joint name='finger_2_joint_2' type='revolute'>
      <child>finger_2_link_2</child>
      <parent>finger_2_link_1</parent>
      <axis>
        <xyz>-0 7e-06 -1</xyz>
        <limit>
          <lower>0</lower>
          <upper>1.5708</upper>
          <effort>100</effort>
          <velocity>100</velocity>
        </limit>
        <dynamics>
          <spring_reference>0</spring_reference>
          <spring_stiffness>0</spring_stiffness>
        </dynamics>
        <use_parent_model_frame>1</use_parent_model_frame>
      </axis>
    </joint>
    <link name='finger_2_link_3'>
      <pose frame=''>-0.092961 0.125207 -0.035999 3.14159 -6e-06 2.09159</pose>
      <inertial>
        <pose frame=''>0 0 0 0 -0 0</pose>
        <mass>0.05</mass>
        <inertia>
          <ixx>0.001239</ixx>
          <ixy>-0.000251</ixy>
          <ixz>1.9e-05</ixz>
          <iyy>0.00085</iyy>
          <iyz>0</iyz>
          <izz>0.001632</izz>
        </inertia>
      </inertial>
      <collision name='finger_2_link_3_collision'>
        <pose frame=''>0 0 0 0 -0 0.52</pose>
        <geometry>
          <mesh>
            <scale>1 1 1</scale>
            <uri>model://robotiq_3f_gripper_visualization/meshes/robotiq-3f-gripper_articulated/collision/link_3.STL</uri>
          </mesh>
        </geometry>
      </collision>
      <visual name='finger_2_link_3_visual'>
        <pose frame=''>0 0 0 0 -0 0.52</pose>
        <geometry>
          <mesh>
            <scale>1 1 1</scale>
            <uri>model://robotiq_3f_gripper_visualization/meshes/robotiq-3f-gripper_articulated/visual/link_3.STL</uri>
          </mesh>
        </geometry>
      </visual>
    </link>
    <joint name='finger_2_joint_3' type='revolute'>
      <child>finger_2_link_3</child>
      <parent>finger_2_link_2</parent>
      <axis>
        <xyz>-0 7e-06 -1</xyz>
        <limit>
          <lower>-1.2217</lower>
          <upper>-0.0523</upper>
          <effort>100</effort>
          <velocity>100</velocity>
        </limit>
        <dynamics>
          <spring_reference>0</spring_reference>
          <spring_stiffness>0</spring_stiffness>
        </dynamics>
        <use_parent_model_frame>1</use_parent_model_frame>
      </axis>
    </joint>
    <link name='finger_middle_link_1'>
      <pose frame=''>0.045516 0.0414 0 0 -0 1.57</pose>
      <inertial>
        <pose frame=''>0 0 0 0 -0 0</pose>
        <mass>0.15</mass>
        <inertia>
          <ixx>0.001859</ixx>
          <ixy>-0.000376</ixy>
          <ixz>2.8e-05</ixz>
          <iyy>0.012756</iyy>
          <iyz>0</iyz>
          <izz>0.0024</izz>
        </inertia>
      </inertial>
      <collision name='finger_middle_link_1_collision'>
        <pose frame=''>0.05 -0.028 0 0 0 -0.52</pose>
        <geometry>
          <mesh>
            <scale>1 1 1</scale>
            <uri>model://robotiq_3f_gripper_visualization/meshes/robotiq-3f-gripper_articulated/collision/link_1.STL</uri>
          </mesh>
        </geometry>
      </collision>
      <visual name='finger_middle_link_1_visual'>
        <pose frame=''>0.05 -0.028 0 0 0 -0.52</pose>
        <geometry>
          <mesh>
            <scale>1 1 1</scale>
            <uri>model://robotiq_3f_gripper_visualization/meshes/robotiq-3f-gripper_articulated/visual/link_1.STL</uri>
          </mesh>
        </geometry>
      </visual>
    </link>
    <joint name='finger_middle_joint_1' type='revolute'>
      <child>finger_middle_link_1</child>
      <parent>palm</parent>
      <axis>
        <xyz>0 0 1</xyz>
        <limit>
          <lower>0.0495</lower>
          <upper>1.2218</upper>
          <effort>100</effort>
          <velocity>100</velocity>
        </limit>
        <dynamics>
          <spring_reference>0</spring_reference>
          <spring_stiffness>0</spring_stiffness>
        </dynamics>
        <use_parent_model_frame>1</use_parent_model_frame>
      </axis>
    </joint>
    <link name='finger_middle_link_2'>
      <pose frame=''>0.073556 0.091378 0 0 -0 1.05</pose>
      <inertial>
        <pose frame=''>0 0 0 0 -0 0</pose>
        <mass>0.15</mass>
        <inertia>
          <ixx>0.001859</ixx>
          <ixy>-0.000376</ixy>
          <ixz>2.8e-05</ixz>
          <iyy>0.012756</iyy>
          <iyz>0</iyz>
          <izz>0.0024</izz>
        </inertia>
      </inertial>
      <collision name='finger_middle_link_2_collision'>
        <pose frame=''>0.039 0 0.0075 0 -0 0</pose>
        <geometry>
          <mesh>
            <scale>1 1 1</scale>
            <uri>model://robotiq_3f_gripper_visualization/meshes/robotiq-3f-gripper_articulated/collision/link_2.STL</uri>
          </mesh>
        </geometry>
      </collision>
      <visual name='finger_middle_link_2_visual'>
        <pose frame=''>0.039 0 0.0075 0 -0 0</pose>
        <geometry>
          <mesh>
            <scale>1 1 1</scale>
            <uri>model://robotiq_3f_gripper_visualization/meshes/robotiq-3f-gripper_articulated/visual/link_2.STL</uri>
          </mesh>
        </geometry>
      </visual>
    </link>
    <joint name='finger_middle_joint_2' type='revolute'>
      <child>finger_middle_link_2</child>
      <parent>finger_middle_link_1</parent>
      <axis>
        <xyz>0 0 1</xyz>
        <limit>
          <lower>0</lower>
          <upper>1.5708</upper>
          <effort>100</effort>
          <velocity>100</velocity>
        </limit>
        <dynamics>
          <spring_reference>0</spring_reference>
          <spring_stiffness>0</spring_stiffness>
        </dynamics>
        <use_parent_model_frame>1</use_parent_model_frame>
      </axis>
    </joint>
    <link name='finger_middle_link_3'>
      <pose frame=''>0.092961 0.125207 0 0 -0 1.05</pose>
      <inertial>
        <pose frame=''>0 0 0 0 -0 0</pose>
        <mass>0.05</mass>
        <inertia>
          <ixx>0.001239</ixx>
          <ixy>-0.000251</ixy>
          <ixz>1.9e-05</ixz>
          <iyy>0.00085</iyy>
          <iyz>0</iyz>
          <izz>0.001632</izz>
        </inertia>
      </inertial>
      <collision name='finger_middle_link_3_collision'>
        <pose frame=''>0 0 0 0 -0 0.52</pose>
        <geometry>
          <mesh>
            <scale>1 1 1</scale>
            <uri>model://robotiq_3f_gripper_visualization/meshes/robotiq-3f-gripper_articulated/collision/link_3.STL</uri>
          </mesh>
        </geometry>
      </collision>
      <visual name='finger_middle_link_3_visual'>
        <pose frame=''>0 0 0 0 -0 0.52</pose>
        <geometry>
          <mesh>
            <scale>1 1 1</scale>
            <uri>model://robotiq_3f_gripper_visualization/meshes/robotiq-3f-gripper_articulated/visual/link_3.STL</uri>
          </mesh>
        </geometry>
      </visual>
    </link>
    <joint name='finger_middle_joint_3' type='revolute'>
      <child>finger_middle_link_3</child>
      <parent>finger_middle_link_2</parent>
      <axis>
        <xyz>0 0 1</xyz>
        <limit>
          <lower>-1.2217</lower>
          <upper>-0.0523</upper>
          <effort>100</effort>
          <velocity>100</velocity>
        </limit>
        <dynamics>
          <spring_reference>0</spring_reference>
          <spring_stiffness>0</spring_stiffness>
        </dynamics>
        <use_parent_model_frame>1</use_parent_model_frame>
      </axis>
    </joint>
  </model>
</sdf>
