<sdf version='1.6'>
  <model name='segbot'>
    <link name='base_footprint'>
      <pose frame=''>0 0 0 0 -0 0</pose>
      <inertial>
        <pose frame=''>-0.001909 0.000407 0.060981 0 -0 0</pose>
        <mass>33.606</mass>
        <inertia>
          <ixx>3001.64</ixx>
          <ixy>-0.00193686</ixy>
          <ixz>0.0550626</ixz>
          <iyy>3001.66</iyy>
          <iyz>0.0135636</iyz>
          <izz>30.4546</izz>
        </inertia>
      </inertial>
      <collision name='base_footprint_fixed_joint_lump__base_link_collision'>
        <pose frame=''>0 0 0.1665 0 -0 0</pose>
        <geometry>
          <cylinder>
            <length>0.333</length>
            <radius>0.305</radius>
          </cylinder>
        </geometry>
        <surface>
          <contact>
            <ode>
              <kp>1e+06</kp>
              <kd>1</kd>
            </ode>
          </contact>
          <friction>
            <ode>
              <mu>1</mu>
              <mu2>1</mu2>
            </ode>
          </friction>
        </surface>
      </collision>
      <collision name='base_footprint_fixed_joint_lump__laser_obstacle_collision_1'>
        <pose frame=''>0 0 0.533 0 -0 0</pose>
        <geometry>
          <box>
            <size>0.25 0.6 0.4</size>
          </box>
        </geometry>
      </collision>
      <visual name='base_footprint_visual'>
        <pose frame=''>0 0 0 0 -0 0</pose>
        <geometry>
          <box>
            <size>0.001 0.001 0.001</size>
          </box>
        </geometry>
      </visual>
      <visual name='base_footprint_fixed_joint_lump__base_link_visual_1'>
        <pose frame=''>0 0 0.2165 0 -0 0</pose>
        <geometry>
          <mesh>
            <scale>0.0254 0.0254 0.0254</scale>
            <uri>model://segbot_description/meshes/rmp50-base-link.dae</uri>
          </mesh>
        </geometry>
        <material>
          <script>
            <uri>__default__</uri>
            <name>__default__</name>
          </script>
        </material>
      </visual>
      <visual name='base_footprint_fixed_joint_lump__chassis_base_plate_link_visual_2'>
        <pose frame=''>0 0 0.327625 0 -0 0</pose>
        <geometry>
          <box>
            <size>0.4064 0.3556 0.00635</size>
          </box>
        </geometry>
        <material>
          <script>
            <name>Gazebo/Grey</name>
            <uri>file://media/materials/scripts/gazebo.material</uri>
          </script>
        </material>
      </visual>
      <visual name='base_footprint_fixed_joint_lump__back_base_beam_link_visual_3'>
        <pose frame=''>-0.1651 -0 0.3435 1.5708 -0 0</pose>
        <geometry>
          <box>
            <size>0.0254 0.0254 0.3048</size>
          </box>
        </geometry>
        <material>
          <script>
            <name>Gazebo/Grey</name>
            <uri>file://media/materials/scripts/gazebo.material</uri>
          </script>
        </material>
      </visual>
      <visual name='base_footprint_fixed_joint_lump__back_left_vertical_beam_link_visual_4'>
        <pose frame=''>-0.1651 0.1397 0.6483 0 -0 0</pose>
        <geometry>
          <box>
            <size>0.0254 0.0254 0.6096</size>
          </box>
        </geometry>
        <material>
          <script>
            <name>Gazebo/Grey</name>
            <uri>file://media/materials/scripts/gazebo.material</uri>
          </script>
        </material>
      </visual>
      <visual name='base_footprint_fixed_joint_lump__left_laptop_support_beam_link_visual_5'>
        <pose frame=''>-0.0254 0.1651 0.9404 3.14159 -1.57079 -3e-06</pose>
        <geometry>
          <box>
            <size>0.0254 0.0254 0.3048</size>
          </box>
        </geometry>
        <material>
          <script>
            <name>Gazebo/Grey</name>
            <uri>file://media/materials/scripts/gazebo.material</uri>
          </script>
        </material>
      </visual>
      <visual name='base_footprint_fixed_joint_lump__laptop_base_plate_link_visual_6'>
        <pose frame=''>-0.0254 0 0.954688 0 -0 0</pose>
        <geometry>
          <box>
            <size>0.3048 0.3556 0.003175</size>
          </box>
        </geometry>
        <material>
          <script>
            <name>Gazebo/Grey</name>
            <uri>file://media/materials/scripts/gazebo.material</uri>
          </script>
        </material>
      </visual>
      <visual name='base_footprint_fixed_joint_lump__laptop_link_visual_7'>
        <pose frame=''>-0.07874 0 0.9658 0 -0 0</pose>
        <geometry>
          <box>
            <size>0.2286 0.3048 0.01905</size>
          </box>
        </geometry>
        <material>
          <script>
            <name>Gazebo/Grey</name>
            <uri>file://media/materials/scripts/gazebo.material</uri>
          </script>
        </material>
      </visual>
      <visual name='base_footprint_fixed_joint_lump__laptop_screen_link_visual_8'>
        <pose frame=''>0.067201 0 1.08557 1.37445 0 -1.5708</pose>
        <geometry>
          <box>
            <size>0.3048 0.2286 0.01905</size>
          </box>
        </geometry>
        <plugin name='laptop_video_controller' filename='libgazebo_ros_video.so'>
          <height>120</height>
          <width>160</width>
          <topicName>image</topicName>
        </plugin>
        <material>
          <script>
            <name>Gazebo/Grey</name>
            <uri>file://media/materials/scripts/gazebo.material</uri>
          </script>
        </material>
      </visual>
      <visual name='base_footprint_fixed_joint_lump__back_right_vertical_beam_link_visual_9'>
        <pose frame=''>-0.1651 -0.1397 0.6483 0 -0 0</pose>
        <geometry>
          <box>
            <size>0.0254 0.0254 0.6096</size>
          </box>
        </geometry>
        <material>
          <script>
            <name>Gazebo/Grey</name>
            <uri>file://media/materials/scripts/gazebo.material</uri>
          </script>
        </material>
      </visual>
      <visual name='base_footprint_fixed_joint_lump__nav_kinect_sensor_beam_link_visual_10'>
        <pose frame=''>-0.1397 -0 0.6356 3.14159 -1.57079 1.57079</pose>
        <geometry>
          <box>
            <size>0.0254 0.0254 0.3048</size>
          </box>
        </geometry>
        <material>
          <script>
            <name>Gazebo/Grey</name>
            <uri>file://media/materials/scripts/gazebo.material</uri>
          </script>
        </material>
      </visual>
      <visual name='base_footprint_fixed_joint_lump__nav_kinect_base_plate_link_visual_11'>
        <pose frame=''>-0.1397 -0 0.649094 0 0 -0</pose>
        <geometry>
          <box>
            <size>0.1016 0.2286 0.001588</size>
          </box>
        </geometry>
        <material>
          <script>
            <name>Gazebo/Grey</name>
            <uri>file://media/materials/scripts/gazebo.material</uri>
          </script>
        </material>
      </visual>
      <visual name='base_footprint_fixed_joint_lump__nav_kinect_standoff_1_link_visual_12'>
        <pose frame=''>-0.1016 -0.1016 0.675287 0 0 -0</pose>
        <geometry>
          <cylinder>
            <length>0.0508</length>
            <radius>0.003175</radius>
          </cylinder>
        </geometry>
        <material>
          <script>
            <name>Gazebo/Grey</name>
            <uri>file://media/materials/scripts/gazebo.material</uri>
          </script>
        </material>
      </visual>
      <visual name='base_footprint_fixed_joint_lump__nav_kinect_top_plate_link_visual_13'>
        <pose frame=''>-0.1397 -0 0.701481 0 0 -0</pose>
        <geometry>
          <box>
            <size>0.1016 0.2286 0.001588</size>
          </box>
        </geometry>
        <material>
          <script>
            <name>Gazebo/Grey</name>
            <uri>file://media/materials/scripts/gazebo.material</uri>
          </script>
        </material>
      </visual>
      <visual name='base_footprint_fixed_joint_lump__nav_kinect_link_visual_14'>
        <pose frame=''>-0.108458 -0.001716 0.723039 0 0 -0</pose>
        <geometry>
          <mesh>
            <scale>0.001 0.001 0.001</scale>
            <uri>model://pr2_description/meshes/sensors/kinect_v0/kinect.dae</uri>
          </mesh>
        </geometry>
        <material>
          <script>
            <uri>__default__</uri>
            <name>__default__</name>
          </script>
        </material>
      </visual>
      <visual name='base_footprint_fixed_joint_lump__nav_kinect_standoff_2_link_visual_15'>
        <pose frame=''>-0.1016 0.1016 0.675287 0 0 -0</pose>
        <geometry>
          <cylinder>
            <length>0.0508</length>
            <radius>0.003175</radius>
          </cylinder>
        </geometry>
        <material>
          <script>
            <name>Gazebo/Grey</name>
            <uri>file://media/materials/scripts/gazebo.material</uri>
          </script>
        </material>
      </visual>
      <visual name='base_footprint_fixed_joint_lump__nav_kinect_standoff_3_link_visual_16'>
        <pose frame=''>-0.1778 0.1016 0.675287 0 0 -0</pose>
        <geometry>
          <cylinder>
            <length>0.0508</length>
            <radius>0.003175</radius>
          </cylinder>
        </geometry>
        <material>
          <script>
            <name>Gazebo/Grey</name>
            <uri>file://media/materials/scripts/gazebo.material</uri>
          </script>
        </material>
      </visual>
      <visual name='base_footprint_fixed_joint_lump__nav_kinect_standoff_4_link_visual_17'>
        <pose frame=''>-0.1778 -0.1016 0.675287 0 0 -0</pose>
        <geometry>
          <cylinder>
            <length>0.0508</length>
            <radius>0.003175</radius>
          </cylinder>
        </geometry>
        <material>
          <script>
            <name>Gazebo/Grey</name>
            <uri>file://media/materials/scripts/gazebo.material</uri>
          </script>
        </material>
      </visual>
      <visual name='base_footprint_fixed_joint_lump__right_laptop_support_beam_link_visual_18'>
        <pose frame=''>-0.0254 -0.1651 0.9404 3.14159 -1.57079 -3e-06</pose>
        <geometry>
          <box>
            <size>0.0254 0.0254 0.3048</size>
          </box>
        </geometry>
        <material>
          <script>
            <name>Gazebo/Grey</name>
            <uri>file://media/materials/scripts/gazebo.material</uri>
          </script>
        </material>
      </visual>
      <visual name='base_footprint_fixed_joint_lump__battery_box_link_visual_19'>
        <pose frame=''>-0.0508 0 0.4705 0 -0 0</pose>
        <geometry>
          <box>
            <size>0.1778 0.3556 0.2794</size>
          </box>
        </geometry>
        <material>
          <script>
            <name>Gazebo/Black</name>
            <uri>file://media/materials/scripts/gazebo.material</uri>
          </script>
        </material>
      </visual>
      <visual name='base_footprint_fixed_joint_lump__chassis_left_plate_link_visual_20'>
        <pose frame=''>0 0.174625 0.27365 -1.5708 0 0</pose>
        <geometry>
          <box>
            <size>0.4064 0.1016 0.00635</size>
          </box>
        </geometry>
        <material>
          <script>
            <name>Gazebo/Grey</name>
            <uri>file://media/materials/scripts/gazebo.material</uri>
          </script>
        </material>
      </visual>
      <visual name='base_footprint_fixed_joint_lump__chassis_right_plate_link_visual_21'>
        <pose frame=''>0 -0.174625 0.27365 1.5708 -0 0</pose>
        <geometry>
          <box>
            <size>0.4064 0.1016 0.00635</size>
          </box>
        </geometry>
        <material>
          <script>
            <name>Gazebo/Grey</name>
            <uri>file://media/materials/scripts/gazebo.material</uri>
          </script>
        </material>
      </visual>
      <visual name='base_footprint_fixed_joint_lump__front_base_beam_link_visual_22'>
        <pose frame=''>0.1143 -0 0.3435 1.5708 -0 0</pose>
        <geometry>
          <box>
            <size>0.0254 0.0254 0.3048</size>
          </box>
        </geometry>
        <material>
          <script>
            <name>Gazebo/Grey</name>
            <uri>file://media/materials/scripts/gazebo.material</uri>
          </script>
        </material>
      </visual>
      <visual name='base_footprint_fixed_joint_lump__front_left_vertical_beam_link_visual_23'>
        <pose frame=''>0.1143 0.1397 0.8007 0 -0 0</pose>
        <geometry>
          <box>
            <size>0.0254 0.0254 0.9144</size>
          </box>
        </geometry>
        <material>
          <script>
            <name>Gazebo/Grey</name>
            <uri>file://media/materials/scripts/gazebo.material</uri>
          </script>
        </material>
      </visual>
      <visual name='base_footprint_fixed_joint_lump__hokuyo_sonar_sensor_beam_link_visual_24'>
        <pose frame=''>0.1397 -0 0.4578 -3.14159 1.57079 1.57079</pose>
        <geometry>
          <box>
            <size>0.0254 0.0254 0.3048</size>
          </box>
        </geometry>
        <material>
          <script>
            <name>Gazebo/Grey</name>
            <uri>file://media/materials/scripts/gazebo.material</uri>
          </script>
        </material>
      </visual>
      <visual name='base_footprint_fixed_joint_lump__left_sensor_plate_standoff_link_visual_25'>
        <pose frame=''>0.1397 0.0635 0.47685 -0 -0 -0</pose>
        <geometry>
          <cylinder>
            <length>0.0127</length>
            <radius>0.00635</radius>
          </cylinder>
        </geometry>
        <material>
          <script>
            <name>Gazebo/Grey</name>
            <uri>file://media/materials/scripts/gazebo.material</uri>
          </script>
        </material>
      </visual>
      <visual name='base_footprint_fixed_joint_lump__sensor_plate_link_visual_26'>
        <pose frame=''>0.13335 0 0.4847 -0 -0 -0</pose>
        <geometry>
          <box>
            <size>0.1143 0.2286 0.003</size>
          </box>
        </geometry>
        <material>
          <script>
            <name>Gazebo/Grey</name>
            <uri>file://media/materials/scripts/gazebo.material</uri>
          </script>
        </material>
      </visual>
      <visual name='base_footprint_fixed_joint_lump__sonar_center_link_visual_27'>
        <pose frame=''>-0.084582 0 0.4982 -0 -0 -0</pose>
        <geometry>
          <box>
            <size>0.001 0.001 0.001</size>
          </box>
        </geometry>
      </visual>
      <visual name='base_footprint_fixed_joint_lump__sonar0_rotated_center_link_visual_28'>
        <pose frame=''>-0.084582 0 0.4982 -0 -0 -0.349066</pose>
        <geometry>
          <box>
            <size>0.001 0.001 0.001</size>
          </box>
        </geometry>
      </visual>
      <visual name='base_footprint_fixed_joint_lump__sonar0_link_visual_29'>
        <pose frame=''>0.161976 -0.08974 0.4982 -0 -0 -0.349066</pose>
        <geometry>
          <box>
            <size>0.012 0.044 0.023</size>
          </box>
        </geometry>
      </visual>
      <visual name='base_footprint_fixed_joint_lump__sonar1_link_visual_30'>
        <pose frame=''>0.1778 -0 0.4982 -0 -0 -0</pose>
        <geometry>
          <box>
            <size>0.012 0.044 0.023</size>
          </box>
        </geometry>
      </visual>
      <visual name='base_footprint_fixed_joint_lump__sonar2_rotated_center_link_visual_31'>
        <pose frame=''>-0.084582 0 0.4982 -0 0 0.349066</pose>
        <geometry>
          <box>
            <size>0.001 0.001 0.001</size>
          </box>
        </geometry>
      </visual>
      <visual name='base_footprint_fixed_joint_lump__sonar2_link_visual_32'>
        <pose frame=''>0.161976 0.08974 0.4982 -0 0 0.349066</pose>
        <geometry>
          <box>
            <size>0.012 0.044 0.023</size>
          </box>
        </geometry>
      </visual>
      <visual name='base_footprint_fixed_joint_lump__nav_hokuyo_plate_link_visual_33'>
        <pose frame=''>0.15875 -0 0.443512 -3.14159 0 -0</pose>
        <geometry>
          <box>
            <size>0.0635 0.1016 0.003175</size>
          </box>
        </geometry>
        <material>
          <script>
            <name>Gazebo/Grey</name>
            <uri>file://media/materials/scripts/gazebo.material</uri>
          </script>
        </material>
      </visual>
      <visual name='base_footprint_fixed_joint_lump__nav_hokuyo_link_visual_34'>
        <pose frame=''>0.15875 -0 0.441925 -3.14159 0 -0</pose>
        <geometry>
          <mesh>
            <scale>0.0254 0.0254 0.0254</scale>
            <uri>model://segbot_description/meshes/hokuyo.dae</uri>
          </mesh>
        </geometry>
      </visual>
      <visual name='base_footprint_fixed_joint_lump__right_sensor_plate_standoff_link_visual_35'>
        <pose frame=''>0.1397 -0.0635 0.47685 -0 -0 -0</pose>
        <geometry>
          <cylinder>
            <length>0.0127</length>
            <radius>0.00635</radius>
          </cylinder>
        </geometry>
        <material>
          <script>
            <name>Gazebo/Grey</name>
            <uri>file://media/materials/scripts/gazebo.material</uri>
          </script>
        </material>
      </visual>
      <visual name='base_footprint_fixed_joint_lump__front_right_vertical_beam_link_visual_36'>
        <pose frame=''>0.1143 -0.1397 0.8007 0 -0 0</pose>
        <geometry>
          <box>
            <size>0.0254 0.0254 0.9144</size>
          </box>
        </geometry>
        <material>
          <script>
            <name>Gazebo/Grey</name>
            <uri>file://media/materials/scripts/gazebo.material</uri>
          </script>
        </material>
      </visual>
      <visual name='base_footprint_fixed_joint_lump__front_cap_beam_link_visual_37'>
        <pose frame=''>0.1143 0 1.2706 -1.5708 0 0</pose>
        <geometry>
          <box>
            <size>0.0254 0.0254 0.3048</size>
          </box>
        </geometry>
        <material>
          <script>
            <name>Gazebo/Grey</name>
            <uri>file://media/materials/scripts/gazebo.material</uri>
          </script>
        </material>
      </visual>
      <visual name='base_footprint_fixed_joint_lump__laser_obstacle_visual_38'>
        <pose frame=''>0 0 0.533 0 -0 0</pose>
        <geometry>
          <box>
            <size>0.001 0.001 0.001</size>
          </box>
        </geometry>
      </visual>
      <velocity_decay/>
      <velocity_decay/>
      <velocity_decay/>
      <velocity_decay/>
      <velocity_decay/>
      <velocity_decay/>
      <velocity_decay/>
      <velocity_decay/>
      <velocity_decay/>
      <velocity_decay/>
      <velocity_decay/>
      <velocity_decay/>
      <velocity_decay/>
      <velocity_decay/>
      <sensor name='nav_kinect_link_sensor' type='depth'>
        <always_on>1</always_on>
        <update_rate>20</update_rate>
        <camera name='__default__'>
          <horizontal_fov>0.994838</horizontal_fov>
          <image>
            <format>R8G8B8</format>
            <width>640</width>
            <height>480</height>
          </image>
          <clip>
            <near>0.01</near>
            <far>5</far>
          </clip>
        </camera>
        <plugin name='nav_kinect_frame_controller' filename='libgazebo_ros_openni_kinect.so'>
          <alwaysOn>true</alwaysOn>
          <updateRate>20.0</updateRate>
          <cameraName>nav_kinect</cameraName>
          <imageTopicName>rgb/image_raw</imageTopicName>
          <cameraInfoTopicName>rgb/camera_info</cameraInfoTopicName>
          <depthImageTopicName>depth/image_raw</depthImageTopicName>
          <depthImageCameraInfoTopicName>depth/camera_info</depthImageCameraInfoTopicName>
          <pointCloudTopicName>depth/points</pointCloudTopicName>
          <frameName>nav_kinect_depth_optical_frame</frameName>
          <pointCloudCutoff>0.5</pointCloudCutoff>
          <distortionK1>0.00000001</distortionK1>
          <distortionK2>0.00000001</distortionK2>
          <distortionK3>0.00000001</distortionK3>
          <distortionT1>0.00000001</distortionT1>
          <distortionT2>0.00000001</distortionT2>
        </plugin>
        <pose frame=''>-0.108458 -0.013716 0.723039 0 0 -0</pose>
      </sensor>
      <velocity_decay/>
      <velocity_decay/>
      <velocity_decay/>
      <velocity_decay/>
      <velocity_decay/>
      <velocity_decay/>
      <velocity_decay/>
      <velocity_decay/>
      <velocity_decay/>
      <velocity_decay/>
      <velocity_decay/>
      <velocity_decay/>
      <velocity_decay/>
      <velocity_decay/>
      <sensor name='nav_hokuyo_laser' type='ray'>
        <always_on>1</always_on>
        <update_rate>10</update_rate>
        <visualize>0</visualize>
        <ray>
          <scan>
            <horizontal>
              <samples>640</samples>
              <resolution>1</resolution>
              <min_angle>-1.309</min_angle>
              <max_angle>1.309</max_angle>
            </horizontal>
          </scan>
          <range>
            <min>0.02</min>
            <max>20</max>
            <resolution>0.03</resolution>
          </range>
        </ray>
        <plugin name='gazebo_ros_nav_hokuyo_laser_controller' filename='libgazebo_ros_laser.so'>
          <gaussianNoise>0.0</gaussianNoise>
          <alwaysOn>true</alwaysOn>
          <updateRate>10</updateRate>
          <topicName>scan</topicName>
          <frameName>nav_hokuyo_laser_link</frameName>
        </plugin>
        <pose frame=''>0.15875 0 0.383925 -3.14159 0 -0</pose>
      </sensor>
      <velocity_decay/>
      <velocity_decay/>
      <gravity>1</gravity>
      <velocity_decay/>
      <self_collide>0</self_collide>
    </link>
    <link name='base_caster_support_link'>
      <pose frame=''>-0.3292 0 0.168 0 -0 0</pose>
      <inertial>
        <pose frame=''>0 0 0 0 -0 0</pose>
        <mass>1</mass>
        <inertia>
          <ixx>0.00375</ixx>
          <ixy>0</ixy>
          <ixz>0</ixz>
          <iyy>0.00375</iyy>
          <iyz>0</iyz>
          <izz>0.00375</izz>
        </inertia>
      </inertial>
      <visual name='base_caster_support_link_visual'>
        <pose frame=''>0 0 0 0 -0 0</pose>
        <geometry>
          <mesh>
            <scale>0.0254 0.0254 0.0254</scale>
            <uri>model://segbot_description/meshes/rmp50-castor-link.dae</uri>
          </mesh>
        </geometry>
        <material>
          <script>
            <uri>__default__</uri>
            <name>__default__</name>
          </script>
        </material>
      </visual>
      <gravity>1</gravity>
      <velocity_decay/>
      <self_collide>0</self_collide>
    </link>
    <joint name='base_caster_support_joint' type='revolute'>
      <child>base_caster_support_link</child>
      <parent>base_footprint</parent>
      <axis>
        <xyz>0 0 1</xyz>
        <limit>
          <lower>-1e+16</lower>
          <upper>1e+16</upper>
        </limit>
        <dynamics>
          <spring_reference>0</spring_reference>
          <spring_stiffness>0</spring_stiffness>
        </dynamics>
        <use_parent_model_frame>1</use_parent_model_frame>
      </axis>
    </joint>
    <link name='caster_wheel_link'>
      <pose frame=''>-0.3689 0 0.0762 0 -0 0</pose>
      <inertial>
        <pose frame=''>0 0 0 0 -0 0</pose>
        <mass>2</mass>
        <inertia>
          <ixx>0.003</ixx>
          <ixy>0</ixy>
          <ixz>0</ixz>
          <iyy>0.00581</iyy>
          <iyz>0</iyz>
          <izz>0.003</izz>
        </inertia>
      </inertial>
      <visual name='caster_wheel_link_visual'>
        <pose frame=''>0 0 0 0 -0 0</pose>
        <geometry>
          <mesh>
            <scale>0.0254 0.0254 0.0254</scale>
            <uri>model://segbot_description/meshes/rmp50-castor-wheel.dae</uri>
          </mesh>
        </geometry>
        <material>
          <script>
            <uri>__default__</uri>
            <name>__default__</name>
          </script>
        </material>
      </visual>
      <gravity>1</gravity>
      <velocity_decay/>
      <self_collide>0</self_collide>
    </link>
    <joint name='caster_wheel_joint' type='revolute'>
      <child>caster_wheel_link</child>
      <parent>base_caster_support_link</parent>
      <axis>
        <xyz>0 1 0</xyz>
        <limit>
          <lower>-1e+16</lower>
          <upper>1e+16</upper>
        </limit>
        <dynamics>
          <spring_reference>0</spring_reference>
          <spring_stiffness>0</spring_stiffness>
        </dynamics>
        <use_parent_model_frame>1</use_parent_model_frame>
      </axis>
    </joint>
    <link name='base_link_left_wheel_link'>
      <pose frame=''>0 0.2689 0.2404 0 -0 0</pose>
      <inertial>
        <pose frame=''>0 0 0 0 -0 0</pose>
        <mass>5</mass>
        <inertia>
          <ixx>0.076</ixx>
          <ixy>0</ixy>
          <ixz>0</ixz>
          <iyy>0.144</iyy>
          <iyz>0</iyz>
          <izz>0.076</izz>
        </inertia>
      </inertial>
      <visual name='base_link_left_wheel_link_visual'>
        <pose frame=''>0 0 0 0 -0 0</pose>
        <geometry>
          <mesh>
            <scale>0.0254 0.0254 0.0254</scale>
            <uri>model://segbot_description/meshes/rmp50-left-wheel.dae</uri>
          </mesh>
        </geometry>
        <material>
          <script>
            <uri>__default__</uri>
            <name>__default__</name>
          </script>
        </material>
      </visual>
      <gravity>1</gravity>
      <velocity_decay/>
      <self_collide>0</self_collide>
    </link>
    <joint name='base_link_left_wheel_joint' type='revolute'>
      <child>base_link_left_wheel_link</child>
      <parent>base_footprint</parent>
      <axis>
        <xyz>0 1 0</xyz>
        <limit>
          <lower>-1e+16</lower>
          <upper>1e+16</upper>
        </limit>
        <dynamics>
          <spring_reference>0</spring_reference>
          <spring_stiffness>0</spring_stiffness>
        </dynamics>
        <use_parent_model_frame>1</use_parent_model_frame>
      </axis>
    </joint>
    <link name='base_link_right_wheel_link'>
      <pose frame=''>0 -0.2689 0.2404 0 -0 0</pose>
      <inertial>
        <pose frame=''>0 0 0 0 -0 0</pose>
        <mass>5</mass>
        <inertia>
          <ixx>0.076</ixx>
          <ixy>0</ixy>
          <ixz>0</ixz>
          <iyy>0.144</iyy>
          <iyz>0</iyz>
          <izz>0.076</izz>
        </inertia>
      </inertial>
      <visual name='base_link_right_wheel_link_visual'>
        <pose frame=''>0 0 0 0 -0 0</pose>
        <geometry>
          <mesh>
            <scale>0.0254 0.0254 0.0254</scale>
            <uri>model://segbot_description/meshes/rmp50-right-wheel.dae</uri>
          </mesh>
        </geometry>
        <material>
          <script>
            <uri>__default__</uri>
            <name>__default__</name>
          </script>
        </material>
      </visual>
      <gravity>1</gravity>
      <velocity_decay/>
      <self_collide>0</self_collide>
    </link>
    <joint name='base_link_right_wheel_joint' type='revolute'>
      <child>base_link_right_wheel_link</child>
      <parent>base_footprint</parent>
      <axis>
        <xyz>0 1 0</xyz>
        <limit>
          <lower>-1e+16</lower>
          <upper>1e+16</upper>
        </limit>
        <dynamics>
          <spring_reference>0</spring_reference>
          <spring_stiffness>0</spring_stiffness>
        </dynamics>
        <use_parent_model_frame>1</use_parent_model_frame>
      </axis>
    </joint>
    <static>0</static>
    <plugin name='object_controller' filename='libgazebo_ros_planar_move.so'>
      <commandTopic>cmd_vel</commandTopic>
      <odometryTopic>odom</odometryTopic>
      <odometryFrame>odom</odometryFrame>
      <robotBaseFrame>base_footprint</robotBaseFrame>
      <odometryRate>100</odometryRate>
    </plugin>
  </model>
</sdf>
